[2025-07-04T15:53:39.188+0530] {taskinstance.py:1159} INFO - Dependencies all met for dep_context=non-requeueable deps ti=<TaskInstance: retail_etl_dag.clean_data scheduled__2025-07-03T00:00:00+00:00 [queued]>
[2025-07-04T15:53:39.194+0530] {taskinstance.py:1159} INFO - Dependencies all met for dep_context=requeueable deps ti=<TaskInstance: retail_etl_dag.clean_data scheduled__2025-07-03T00:00:00+00:00 [queued]>
[2025-07-04T15:53:39.194+0530] {taskinstance.py:1361} INFO - Starting attempt 2 of 2
[2025-07-04T15:53:39.208+0530] {taskinstance.py:1382} INFO - Executing <Task(BashOperator): clean_data> on 2025-07-03 00:00:00+00:00
[2025-07-04T15:53:39.211+0530] {standard_task_runner.py:57} INFO - Started process 25774 to run task
[2025-07-04T15:53:39.219+0530] {standard_task_runner.py:84} INFO - Running: ['airflow', 'tasks', 'run', 'retail_etl_dag', 'clean_data', 'scheduled__2025-07-03T00:00:00+00:00', '--job-id', '30', '--raw', '--subdir', 'DAGS_FOLDER/retail_etl_dag.py', '--cfg-path', '/var/folders/53/tbd296vx2878lwlskxvm_8h80000gp/T/tmpujkuebwh']
[2025-07-04T15:53:39.222+0530] {standard_task_runner.py:85} INFO - Job 30: Subtask clean_data
[2025-07-04T15:53:39.274+0530] {task_command.py:416} INFO - Running <TaskInstance: retail_etl_dag.clean_data scheduled__2025-07-03T00:00:00+00:00 [running]> on host v-macbook-pro.local
[2025-07-04T15:53:39.332+0530] {taskinstance.py:1662} INFO - Exporting env vars: AIRFLOW_CTX_DAG_OWNER='airflow' AIRFLOW_CTX_DAG_ID='retail_etl_dag' AIRFLOW_CTX_TASK_ID='clean_data' AIRFLOW_CTX_EXECUTION_DATE='2025-07-03T00:00:00+00:00' AIRFLOW_CTX_TRY_NUMBER='2' AIRFLOW_CTX_DAG_RUN_ID='scheduled__2025-07-03T00:00:00+00:00'
[2025-07-04T15:53:39.335+0530] {subprocess.py:63} INFO - Tmp dir root location: /var/folders/53/tbd296vx2878lwlskxvm_8h80000gp/T
[2025-07-04T15:53:39.336+0530] {subprocess.py:75} INFO - Running command: ['/bin/bash', '-c', 'spark-submit /Users/vaish/databorn_etl_project/retail_etl/etl_pipeline_project/spark_jobs/clean_data.py --input "/Users/vaish/databorn_etl_project/retail_etl/etl_pipeline_project/data/raw/OnlineRetail.csv" --output "/Users/vaish/databorn_etl_project/retail_etl/etl_pipeline_project/data/processed/cleaned_data.csv"']
[2025-07-04T15:53:39.344+0530] {subprocess.py:86} INFO - Output:
[2025-07-04T15:53:39.490+0530] {subprocess.py:93} INFO - Traceback (most recent call last):
[2025-07-04T15:53:39.496+0530] {subprocess.py:93} INFO -   File "/Users/vaish/databorn_etl_project/retail_etl/etl_pipeline_project/venv/bin/find_spark_home.py", line 95, in <module>
[2025-07-04T15:53:39.497+0530] {subprocess.py:93} INFO -     print(_find_spark_home())
[2025-07-04T15:53:39.497+0530] {subprocess.py:93} INFO -           ~~~~~~~~~~~~~~~~^^
[2025-07-04T15:53:39.498+0530] {subprocess.py:93} INFO -   File "/Users/vaish/databorn_etl_project/retail_etl/etl_pipeline_project/venv/bin/find_spark_home.py", line 59, in _find_spark_home
[2025-07-04T15:53:39.498+0530] {subprocess.py:93} INFO -     module_home = os.path.dirname(find_spec("pyspark").origin)
[2025-07-04T15:53:39.498+0530] {subprocess.py:93} INFO -                                   ^^^^^^^^^^^^^^^^^^^^^^^^^^^
[2025-07-04T15:53:39.499+0530] {subprocess.py:93} INFO - AttributeError: 'NoneType' object has no attribute 'origin'
[2025-07-04T15:53:39.506+0530] {subprocess.py:93} INFO - /Users/vaish/databorn_etl_project/retail_etl/etl_pipeline_project/venv/bin/spark-submit: line 27: /bin/spark-class: No such file or directory
[2025-07-04T15:53:39.506+0530] {subprocess.py:93} INFO - /Users/vaish/databorn_etl_project/retail_etl/etl_pipeline_project/venv/bin/spark-submit: line 27: exec: /bin/spark-class: cannot execute: No such file or directory
[2025-07-04T15:53:39.507+0530] {subprocess.py:97} INFO - Command exited with return code 126
[2025-07-04T15:53:39.515+0530] {taskinstance.py:1937} ERROR - Task failed with exception
Traceback (most recent call last):
  File "/Users/vaish/databorn_etl_project/retail_etl/etl_pipeline_project/venv/lib/python3.10/site-packages/airflow/operators/bash.py", line 210, in execute
    raise AirflowException(
airflow.exceptions.AirflowException: Bash command failed. The command returned a non-zero exit code 126.
[2025-07-04T15:53:39.521+0530] {taskinstance.py:1400} INFO - Marking task as FAILED. dag_id=retail_etl_dag, task_id=clean_data, execution_date=20250703T000000, start_date=20250704T102339, end_date=20250704T102339
[2025-07-04T15:53:39.533+0530] {standard_task_runner.py:104} ERROR - Failed to execute job 30 for task clean_data (Bash command failed. The command returned a non-zero exit code 126.; 25774)
[2025-07-04T15:53:39.556+0530] {local_task_job_runner.py:228} INFO - Task exited with return code 1
[2025-07-04T15:53:39.578+0530] {taskinstance.py:2778} INFO - 0 downstream tasks scheduled from follow-on schedule check
[2025-07-04T16:09:55.287+0530] {taskinstance.py:1159} INFO - Dependencies all met for dep_context=non-requeueable deps ti=<TaskInstance: retail_etl_dag.clean_data scheduled__2025-07-03T00:00:00+00:00 [queued]>
[2025-07-04T16:09:55.294+0530] {taskinstance.py:1159} INFO - Dependencies all met for dep_context=requeueable deps ti=<TaskInstance: retail_etl_dag.clean_data scheduled__2025-07-03T00:00:00+00:00 [queued]>
[2025-07-04T16:09:55.295+0530] {taskinstance.py:1361} INFO - Starting attempt 2 of 2
[2025-07-04T16:09:55.310+0530] {taskinstance.py:1382} INFO - Executing <Task(BashOperator): clean_data> on 2025-07-03 00:00:00+00:00
[2025-07-04T16:09:55.313+0530] {standard_task_runner.py:57} INFO - Started process 32544 to run task
[2025-07-04T16:09:55.320+0530] {standard_task_runner.py:84} INFO - Running: ['airflow', 'tasks', 'run', 'retail_etl_dag', 'clean_data', 'scheduled__2025-07-03T00:00:00+00:00', '--job-id', '40', '--raw', '--subdir', 'DAGS_FOLDER/retail_etl_dag.py', '--cfg-path', '/var/folders/53/tbd296vx2878lwlskxvm_8h80000gp/T/tmpru257k8b']
[2025-07-04T16:09:55.325+0530] {standard_task_runner.py:85} INFO - Job 40: Subtask clean_data
[2025-07-04T16:09:55.378+0530] {task_command.py:416} INFO - Running <TaskInstance: retail_etl_dag.clean_data scheduled__2025-07-03T00:00:00+00:00 [running]> on host v-macbook-pro.local
[2025-07-04T16:09:55.436+0530] {taskinstance.py:1662} INFO - Exporting env vars: AIRFLOW_CTX_DAG_OWNER='airflow' AIRFLOW_CTX_DAG_ID='retail_etl_dag' AIRFLOW_CTX_TASK_ID='clean_data' AIRFLOW_CTX_EXECUTION_DATE='2025-07-03T00:00:00+00:00' AIRFLOW_CTX_TRY_NUMBER='2' AIRFLOW_CTX_DAG_RUN_ID='scheduled__2025-07-03T00:00:00+00:00'
[2025-07-04T16:09:55.439+0530] {subprocess.py:63} INFO - Tmp dir root location: /var/folders/53/tbd296vx2878lwlskxvm_8h80000gp/T
[2025-07-04T16:09:55.440+0530] {subprocess.py:75} INFO - Running command: ['/bin/bash', '-c', 'spark-submit /Users/vaish/databorn_etl_project/retail_etl/etl_pipeline_project/spark_jobs/clean_data.py --input "/Users/vaish/databorn_etl_project/retail_etl/etl_pipeline_project/data/raw/OnlineRetail.csv" --output "/Users/vaish/databorn_etl_project/retail_etl/etl_pipeline_project/data/processed/cleaned_data.csv"']
[2025-07-04T16:09:55.447+0530] {subprocess.py:86} INFO - Output:
[2025-07-04T16:09:55.526+0530] {subprocess.py:93} INFO - Traceback (most recent call last):
[2025-07-04T16:09:55.530+0530] {subprocess.py:93} INFO -   File "/Users/vaish/databorn_etl_project/retail_etl/etl_pipeline_project/venv/bin/find_spark_home.py", line 95, in <module>
[2025-07-04T16:09:55.531+0530] {subprocess.py:93} INFO -     print(_find_spark_home())
[2025-07-04T16:09:55.531+0530] {subprocess.py:93} INFO -           ~~~~~~~~~~~~~~~~^^
[2025-07-04T16:09:55.531+0530] {subprocess.py:93} INFO -   File "/Users/vaish/databorn_etl_project/retail_etl/etl_pipeline_project/venv/bin/find_spark_home.py", line 59, in _find_spark_home
[2025-07-04T16:09:55.532+0530] {subprocess.py:93} INFO -     module_home = os.path.dirname(find_spec("pyspark").origin)
[2025-07-04T16:09:55.532+0530] {subprocess.py:93} INFO -                                   ^^^^^^^^^^^^^^^^^^^^^^^^^^^
[2025-07-04T16:09:55.532+0530] {subprocess.py:93} INFO - AttributeError: 'NoneType' object has no attribute 'origin'
[2025-07-04T16:09:55.539+0530] {subprocess.py:93} INFO - /Users/vaish/databorn_etl_project/retail_etl/etl_pipeline_project/venv/bin/spark-submit: line 27: /bin/spark-class: No such file or directory
[2025-07-04T16:09:55.539+0530] {subprocess.py:93} INFO - /Users/vaish/databorn_etl_project/retail_etl/etl_pipeline_project/venv/bin/spark-submit: line 27: exec: /bin/spark-class: cannot execute: No such file or directory
[2025-07-04T16:09:55.540+0530] {subprocess.py:97} INFO - Command exited with return code 126
[2025-07-04T16:09:55.548+0530] {taskinstance.py:1937} ERROR - Task failed with exception
Traceback (most recent call last):
  File "/Users/vaish/databorn_etl_project/retail_etl/etl_pipeline_project/venv/lib/python3.10/site-packages/airflow/operators/bash.py", line 210, in execute
    raise AirflowException(
airflow.exceptions.AirflowException: Bash command failed. The command returned a non-zero exit code 126.
[2025-07-04T16:09:55.553+0530] {taskinstance.py:1400} INFO - Marking task as FAILED. dag_id=retail_etl_dag, task_id=clean_data, execution_date=20250703T000000, start_date=20250704T103955, end_date=20250704T103955
[2025-07-04T16:09:55.570+0530] {standard_task_runner.py:104} ERROR - Failed to execute job 40 for task clean_data (Bash command failed. The command returned a non-zero exit code 126.; 32544)
[2025-07-04T16:09:55.617+0530] {local_task_job_runner.py:228} INFO - Task exited with return code 1
[2025-07-04T16:09:55.640+0530] {taskinstance.py:2778} INFO - 0 downstream tasks scheduled from follow-on schedule check
