[2025-07-04T16:04:33.835+0530] {taskinstance.py:1159} INFO - Dependencies all met for dep_context=non-requeueable deps ti=<TaskInstance: retail_etl_dag.clean_data manual__2025-07-04T10:34:23.354467+00:00 [queued]>
[2025-07-04T16:04:33.841+0530] {taskinstance.py:1159} INFO - Dependencies all met for dep_context=requeueable deps ti=<TaskInstance: retail_etl_dag.clean_data manual__2025-07-04T10:34:23.354467+00:00 [queued]>
[2025-07-04T16:04:33.841+0530] {taskinstance.py:1361} INFO - Starting attempt 1 of 2
[2025-07-04T16:04:33.857+0530] {taskinstance.py:1382} INFO - Executing <Task(BashOperator): clean_data> on 2025-07-04 10:34:23.354467+00:00
[2025-07-04T16:04:33.860+0530] {standard_task_runner.py:57} INFO - Started process 31313 to run task
[2025-07-04T16:04:33.868+0530] {standard_task_runner.py:84} INFO - Running: ['airflow', 'tasks', 'run', 'retail_etl_dag', 'clean_data', 'manual__2025-07-04T10:34:23.354467+00:00', '--job-id', '34', '--raw', '--subdir', 'DAGS_FOLDER/retail_etl_dag.py', '--cfg-path', '/var/folders/53/tbd296vx2878lwlskxvm_8h80000gp/T/tmpf2s2hkcm']
[2025-07-04T16:04:33.871+0530] {standard_task_runner.py:85} INFO - Job 34: Subtask clean_data
[2025-07-04T16:04:33.921+0530] {task_command.py:416} INFO - Running <TaskInstance: retail_etl_dag.clean_data manual__2025-07-04T10:34:23.354467+00:00 [running]> on host v-macbook-pro.local
[2025-07-04T16:04:33.981+0530] {taskinstance.py:1662} INFO - Exporting env vars: AIRFLOW_CTX_DAG_OWNER='airflow' AIRFLOW_CTX_DAG_ID='retail_etl_dag' AIRFLOW_CTX_TASK_ID='clean_data' AIRFLOW_CTX_EXECUTION_DATE='2025-07-04T10:34:23.354467+00:00' AIRFLOW_CTX_TRY_NUMBER='1' AIRFLOW_CTX_DAG_RUN_ID='manual__2025-07-04T10:34:23.354467+00:00'
[2025-07-04T16:04:33.984+0530] {subprocess.py:63} INFO - Tmp dir root location: /var/folders/53/tbd296vx2878lwlskxvm_8h80000gp/T
[2025-07-04T16:04:33.985+0530] {subprocess.py:75} INFO - Running command: ['/bin/bash', '-c', 'spark-submit /Users/vaish/databorn_etl_project/retail_etl/etl_pipeline_project/spark_jobs/clean_data.py --input "/Users/vaish/databorn_etl_project/retail_etl/etl_pipeline_project/data/raw/OnlineRetail.csv" --output "/Users/vaish/databorn_etl_project/retail_etl/etl_pipeline_project/data/processed/cleaned_data.csv"']
[2025-07-04T16:04:33.993+0530] {subprocess.py:86} INFO - Output:
[2025-07-04T16:04:34.197+0530] {subprocess.py:93} INFO - Traceback (most recent call last):
[2025-07-04T16:04:34.207+0530] {subprocess.py:93} INFO -   File "/Users/vaish/databorn_etl_project/retail_etl/etl_pipeline_project/venv/bin/find_spark_home.py", line 95, in <module>
[2025-07-04T16:04:34.207+0530] {subprocess.py:93} INFO -     print(_find_spark_home())
[2025-07-04T16:04:34.208+0530] {subprocess.py:93} INFO -           ~~~~~~~~~~~~~~~~^^
[2025-07-04T16:04:34.208+0530] {subprocess.py:93} INFO -   File "/Users/vaish/databorn_etl_project/retail_etl/etl_pipeline_project/venv/bin/find_spark_home.py", line 59, in _find_spark_home
[2025-07-04T16:04:34.208+0530] {subprocess.py:93} INFO -     module_home = os.path.dirname(find_spec("pyspark").origin)
[2025-07-04T16:04:34.209+0530] {subprocess.py:93} INFO -                                   ^^^^^^^^^^^^^^^^^^^^^^^^^^^
[2025-07-04T16:04:34.209+0530] {subprocess.py:93} INFO - AttributeError: 'NoneType' object has no attribute 'origin'
[2025-07-04T16:04:34.217+0530] {subprocess.py:93} INFO - /Users/vaish/databorn_etl_project/retail_etl/etl_pipeline_project/venv/bin/spark-submit: line 27: /bin/spark-class: No such file or directory
[2025-07-04T16:04:34.218+0530] {subprocess.py:93} INFO - /Users/vaish/databorn_etl_project/retail_etl/etl_pipeline_project/venv/bin/spark-submit: line 27: exec: /bin/spark-class: cannot execute: No such file or directory
[2025-07-04T16:04:34.219+0530] {subprocess.py:97} INFO - Command exited with return code 126
[2025-07-04T16:04:34.228+0530] {taskinstance.py:1937} ERROR - Task failed with exception
Traceback (most recent call last):
  File "/Users/vaish/databorn_etl_project/retail_etl/etl_pipeline_project/venv/lib/python3.10/site-packages/airflow/operators/bash.py", line 210, in execute
    raise AirflowException(
airflow.exceptions.AirflowException: Bash command failed. The command returned a non-zero exit code 126.
[2025-07-04T16:04:34.234+0530] {taskinstance.py:1400} INFO - Marking task as UP_FOR_RETRY. dag_id=retail_etl_dag, task_id=clean_data, execution_date=20250704T103423, start_date=20250704T103433, end_date=20250704T103434
[2025-07-04T16:04:34.246+0530] {standard_task_runner.py:104} ERROR - Failed to execute job 34 for task clean_data (Bash command failed. The command returned a non-zero exit code 126.; 31313)
[2025-07-04T16:04:34.283+0530] {local_task_job_runner.py:228} INFO - Task exited with return code 1
[2025-07-04T16:04:34.308+0530] {taskinstance.py:2778} INFO - 0 downstream tasks scheduled from follow-on schedule check
